Workbook

Sheet Instructions
A1: MS Excel Practical Exam
A2: Total Questions: 30
A3: Difficulty Level: Medium
A4: Syllabus: Formulas, Logical Functions, Lookups, INDEX-MATCH, Pivot Tables & Charts, Data Analysis
A5: Attempt all questions using appropriate Excel tools/functions.

Sheet Product_Master
A1: Product | B1: Category | C1: GST_%
A2: Laptop | B2: Electronics | C2: 18
A3: Mobile | B3: Electronics | C3: 12
A4: Tablet | B4: Electronics | C4: 12

Sheet Sheet2
A3: Row Labels | B3: Sum of Sales
A4: Laptop | B4: 225000
A5: Mobile | B5: 135000
A6: Tablet | B6: 54000
A7: Grand Total | B7: 414000

Sheet Sales_Data
A1: Order_ID | B1: Region | C1: Salesperson | D1: Product | E1: Quantity | F1: Unit_Price | G1: Sales_Date | H1: Gst% | I1: Sales | J1: Gst Amount | K1: Gst AM | L1: Total amount
A2: 301 | B2: North | C2: Amit | D2: Laptop | E2: 2 | F2: 45000 | G2: 05-01-2025 | H2: 0.18 | I2: =F2*E2 -> 90000 | J2: =F2*H2 -> 8100 | K2: =J2*E2 -> 16200 | L2: 106200
A3: 302 | B3: South | C3: Riya | D3: Mobile | E3: 5 | F3: 15000 | G3: 07-01-2025 | H3: 0.12 | I3: =F3*E3 -> 75000 | J3: =F3*H3 -> 1800 | K3: =J3*E3 -> 9000 | L3: 84000
A4: 303 | B4: East | C4: Kunal | D4: Tablet | E4: 3 | F4: 18000 | G4: 10-01-2025 | H4: 0.12 | I4: =F4*E4 -> 54000 | J4: =F4*H4 -> 2160 | K4: =J4*E4 -> 6480 | L4: 60480
A5: 304 | B5: West | C5: Neha | D5: Laptop | E5: 1 | F5: 45000 | G5: 12-01-2025 | H5: 0.18 | I5: =F5*E5 -> 45000 | J5: =F5*H5 -> 8100 | K5: =J5*E5 -> 8100 | L5: 53100
A6: 305 | B6: North | C6: Amit | D6: Mobile | E6: 4 | F6: 15000 | G6: 15-01-2025 | H6: 0.12 | I6: =F6*E6 -> 60000 | J6: =F6*H6 -> 1800 | K6: =J6*E6 -> 7200 | L6: 67200
A7: 306 | B7: South | C7: Riya | D7: Laptop | E7: 2 | F7: 45000 | G7: 18-01-2025 | H7: 0.18 | I7: =F7*E7 -> 90000 | J7: =F7*H7 -> 8100 | K7: =J7*E7 -> 16200 | L7: 106200

Sheet Answer29
A11: 29. Freeze top row in Sales_Data sheet.
A13: Order_ID | B13: Region | C13: Salesperson | D13: Product | E13: Quantity | F13: Unit_Price | G13: Sales_Date | H13: Gst% | I13: Sales
A14: 301 | B14: North | C14: Amit | D14: Laptop | E14: 2 | F14: 45000 | G14: 05-01-2025 | H14: 0.18 | I14: =F14*E14 -> 90000
A15: 302 | B15: South | C15: Riya | D15: Mobile | E15: 5 | F15: 15000 | G15: 07-01-2025 | H15: 0.12 | I15: =F15*E15 -> 75000
A16: 303 | B16: East | C16: Kunal | D16: Tablet | E16: 3 | F16: 18000 | G16: 10-01-2025 | H16: 0.12 | I16: =F16*E16 -> 54000
A17: 304 | B17: West | C17: Neha | D17: Laptop | E17: 1 | F17: 45000 | G17: 12-01-2025 | H17: 0.18 | I17: =F17*E17 -> 45000
A18: 305 | B18: North | C18: Amit | D18: Mobile | E18: 4 | F18: 15000 | G18: 15-01-2025 | H18: 0.12 | I18: =F18*E18 -> 60000
A19: 306 | B19: South | C19: Riya | D19: Laptop | E19: 2 | F19: 45000 | G19: 18-01-2025 | H19: 0.12 | I19: =F19*E19 -> 90000

Sheet Student_Marks
A1: Student_ID | B1: Name | C1: Maths | D1: Statistics | E1: Excel | F1: Attendance_% | H1: Average
A2: 1 | B2: Rahul | C2: 78 | D2: 82 | E2: 85 | F2: 92 | H2: 81.666667 | I2: Eligible | J2: Median | K2: 82
A3: 2 | B3: Sneha | C3: 88 | D3: 91 | E3: 90 | F3: 96 | H3: 89.666667 | I3: Eligible
A4: 3 | B4: Arjun | C4: 65 | D4: 70 | E4: 72 | F4: 85 | H4: 69 | I4: Eligible
A5: 4 | B5: Pooja | C5: 92 | D5: 89 | E5: 94 | F5: 98 | H5: 91.666667 | I5: Eligible
A6: 5 | B6: Vikas | C6: 55 | D6: 60 | E6: 58 | F6: 80 | H6: 57.666667 | I6: Not Eligible
G8: S.D | H8: 14.737707
F9: 3
H11: =_xlfn.CONCAT(A2,B2) -> 1Rahul

Sheet Questions
A1: 1. Calculate Total Sales for each order (Quantity × Unit_Price). | J1: 2
A2: 2. Calculate GST Amount using VLOOKUP from Product_Master. | J2: 2
A3: 3. Find Final Amount payable (Total Sales + GST). | J3: 2
A4: 4. Find Grand Total of Final Amount. | J4: 2
A5: 5. Count total number of orders using COUNTA. | J5: 2
A6: 6. Find Region-wise total sales using SUMIF. | J6: 2
A7: 7. Use IF to classify Quantity as High (>3) or Low (<=3). | J7: 2
A8: 8. Find the maximum and minimum Final Amount. | J8: 2
A9: 9. Extract month name from Sales_Date. | J9: 2
A10: 10. Sort Sales_Data by Final Amount (Descending). | J10: 2
A11: 11. Use INDEX-MATCH to fetch Product Category. | J11: 2
A12: 12. Calculate average marks of each student. | J12: 2
... A30: 30. Protect the Student_Marks sheet. | J30: 2
J32: =SUM(J1:J30) -> 60

Sheet Answer 1 to 28,30
A1: 1. Calculate Total Sales for each order (Quantity × Unit_Price).
B3: Qty. | C3: Unit Price | D3: Total Sales
B4: 2 | C4: 45000 | D4: =C4*B4 -> 90000
B5: 5 | C5: 15000 | D5: =C5*B5 -> 75000
B6: 3 | C6: 18000 | D6: =C6*B6 -> 54000
B7: 1 | C7: 45000 | D7: =C7*B7 -> 45000
B8: 4 | C8: 15000 | D8: =C8*B8 -> 60000
B9: 2 | C9: 45000 | D9: =C9*B9 -> 90000
A11: 2. Calculate GST Amount using VLOOKUP from Product_Master.
B13: Product | C13: Gst % | D13: Gst Amount
B14: Laptop | C14: =VLOOKUP(B14,Product_Master!A1:C4,3,0) -> 18 | D14: =VLOOKUP(B14,Sales_Data!D1:K7,7,0) -> 8100
B15: Mobile | C15: 12 | D15: =VLOOKUP(B15,Sales_Data!D2:K8,7,0) -> 1800
B16: Tablet | C16: 12 | D16: =VLOOKUP(B16,Sales_Data!D3:K9,7,0) -> 2160
A17: 3. Find Final Amount payable (Total Sales + GST).
B18: Product | C18: Final Amount
B19: Laptop | C19: 106200
B20: Mobile | C20: 84000
B21: Tablet | C21: 60480
B22: Laptop | C22: 53100
B23: Mobile | C23: 67200
B24: Laptop | C24: 106200
A26: 4. Find Grand Total of Final Amount.
B28: Grand Total | C28: =SUM(Sales_Data!L1:L7) -> 477180
A30: 5. Count total number of orders using COUNTA.
B32: Total Number Of Orders | C32: =COUNTA(Sales_Data!A2:A7) -> 6
A34: 6. Find Region-wise total sales using SUMIF.
B36: Region | C36: Total Sales
B37: North | C37: =SUMIF(Sales_Data!B2:B7,"North",Sales_Data!K2:K7) -> 23400
B38: South | C38: =SUMIF(Sales_Data!B2:B7,"South",Sales_Data!K2:K8) -> 25200
B39: East | C39: =SUMIF(Sales_Data!B2:B7,"East",Sales_Data!K2:K7) -> 6480
B40: West | C40: =SUMIF(Sales_Data!B2:B7,"west",Sales_Data!K2:K7) -> 8100
A42: 7. Use IF to classify Quantity as High (>3) or Low (<=3).
B44: Quantity | C44: If
B45: 2 | C45: =IF(B45>3,"high","Low") -> Low
B46: 5 | C46: =IF(B46>3,"high","Low") -> high
B47: 3 | C47: =IF(B47>3,"high","Low") -> Low
B48: 1 | C48: =IF(B48>3,"high","Low") -> Low
B49: 4 | C49: =IF(B49>3,"high","Low") -> high
B50: 2 | C50: =IF(B50>3,"high","Low") -> Low
A52: 8. Find the maximum and minimum Final Amount.
...
